{"timestamp": "2025-01-14T02:48:42.855417+00:00", "level": "ERROR", "message": "Server initialization timed out", "logger": "iac_memory_mcp_server", "levelno": 40, "pathname": "/home/herman/Documents/vscode/iac-memory-mcp-server/src/iac_memory_mcp_server/server.py", "filename": "server.py", "module": "server", "exc_text": null, "lineno": 345, "funcName": "run_server", "msecs": 855.0, "relativeCreated": 30254.68101, "thread": 128975397174144, "threadName": "MainThread", "processName": "MainProcess", "process": 54201, "taskName": "server_main"}
{"timestamp": "2025-01-14T02:48:42.857109+00:00", "level": "ERROR", "message": "Server task error", "logger": "iac_memory_mcp_server", "correlation_id": "5002f759-5a9f-4f42-b5ed-ada316fa30db", "operation": "server_tasks", "levelno": 40, "pathname": "/home/herman/Documents/vscode/iac-memory-mcp-server/src/iac_memory_mcp_server/server.py", "filename": "server.py", "module": "server", "exc_text": null, "lineno": 370, "funcName": "run_server", "msecs": 857.0, "relativeCreated": 30256.373119, "thread": 128975397174144, "threadName": "MainThread", "processName": "MainProcess", "process": 54201, "taskName": "server_main", "start_time": 1736822892.8397017, "task_states": {"server_run": "error", "shutdown_wrapper": "starting"}, "error_chain": [{"task": "server_run", "error": "", "error_type": "TimeoutError", "traceback": "Traceback (most recent call last):\n File \"/home/herman/Documents/vscode/iac-memory-mcp-server/.venv/lib/python3.13/site-packages/anyio/streams/memory.py\", line 111, in receive\n return self.receive_nowait()\n ~~~~~~~~~~~~~~~~~~~^^\n File \"/home/herman/Documents/vscode/iac-memory-mcp-server/.venv/lib/python3.13/site-packages/anyio/streams/memory.py\", line 106, in receive_nowait\n raise WouldBlock\nanyio.WouldBlock\n\nDuring handling of the above exception, another exception occurred:\n\nTraceback (most recent call last):\n File \"/home/herman/Documents/vscode/iac-memory-mcp-server/src/iac_memory_mcp_server/server.py\", line 335, in run_server\n await server_future\n File \"/home/herman/Documents/vscode/iac-memory-mcp-server/.venv/lib/python3.13/site-packages/mcp/server/lowlevel/server.py\", line 424, in run\n async with ServerSession(\n ~~~~~~~~~~~~~^\n read_stream, write_stream, initialization_options\n ^^^^^^^^^^^^^^^^^^^^^^^^^^^^^^^^^^^^^^^^^^^^^^^^^\n ) as session:\n ^\n File \"/home/herman/Documents/vscode/iac-memory-mcp-server/.venv/lib/python3.13/site-packages/mcp/shared/session.py\", line 122, in __aexit__\n return await self._task_group.__aexit__(exc_type, exc_val, exc_tb)\n ^^^^^^^^^^^^^^^^^^^^^^^^^^^^^^^^^^^^^^^^^^^^^^^^^^^^^^^^^^^\n File \"/home/herman/Documents/vscode/iac-memory-mcp-server/.venv/lib/python3.13/site-packages/anyio/_backends/_asyncio.py\", line 771, in __aexit__\n raise exc_val\n File \"/home/herman/Documents/vscode/iac-memory-mcp-server/.venv/lib/python3.13/site-packages/mcp/server/lowlevel/server.py\", line 427, in run\n async for message in session.incoming_messages:\n ...<69 lines>...\n )\n File \"/home/herman/Documents/vscode/iac-memory-mcp-server/.venv/lib/python3.13/site-packages/anyio/abc/_streams.py\", line 35, in __anext__\n return await self.receive()\n ^^^^^^^^^^^^^^^^^^^^\n File \"/home/herman/Documents/vscode/iac-memory-mcp-server/.venv/lib/python3.13/site-packages/anyio/streams/memory.py\", line 119, in receive\n await receive_event.wait()\n File \"/home/herman/Documents/vscode/iac-memory-mcp-server/.venv/lib/python3.13/site-packages/anyio/_backends/_asyncio.py\", line 1766, in wait\n await self._event.wait()\n File \"/usr/lib/python3.13/asyncio/locks.py\", line 213, in wait\n await fut\nasyncio.exceptions.CancelledError\n\nThe above exception was the direct cause of the following exception:\n\nTraceback (most recent call last):\n File \"/home/herman/Documents/vscode/iac-memory-mcp-server/src/iac_memory_mcp_server/server.py\", line 307, in run_server\n async with asyncio.timeout(\n ~~~~~~~~~~~~~~~^\n 30.0\n ^^^^\n ): # Increased timeout for initialization\n ^\n File \"/usr/lib/python3.13/asyncio/timeouts.py\", line 116, in __aexit__\n raise TimeoutError from exc_val\nTimeoutError\n"}], "task_durations": {}, "error": "", "error_type": "TimeoutError", "task": "server_run", "duration": 30.017359972000122}